Workbook

Sheet Residents
A1: Flat No. | B1: Owner Name | C1: Resident Name | D1: Occupancy Type | E1: Owner Email | F1: Owner Mobile | G1: Resident Email | H1: Resident Mobile
A2: 101 | B2: Meera Bhatt | C2: Meera Bhatt | D2: Owner | E2: meera_bhatt@demooutlook.com | F2: 1321819600 | G2: meera_bhatt@demooutlook.com | H2: 1321819600
A3: 102 | B3: Rohan Gill | C3: Rohan Gill | D3: Owner | E3: rohan_gill@demoyahoo.com | F3: 1838637940 | G3: rohan_gill@demoyahoo.com | H3: 1838637940
A4: 103 | B4: Mansi Khanna | C4: Mansi Khanna | D4: Owner | E4: mansi_khanna@demooutlook.com | F4: 2235116155 | G4: mansi_khanna@demooutlook.com | H4: 2235116155
A5: 104 | B5: Manish Mukherjee | C5: Shreya Sisodia | D5: Rental | E5: manish_mukherjee@demoyahoo.com | F5: 1618495931 | G5: shreya_sisodia@demogmail.com | H5: 1413164752
A6: 105 | B6: Ayaan Naidu | C6: Ayaan Naidu | D6: Owner | E6: ayaan_naidu@demooutlook.com | F6: 1928327648 | G6: ayaan_naidu@demooutlook.com | H6: 1928327648
A7: 106 | B7: Ankit Pillai | C7: Radhika Jadhav | D7: Rental | E7: ankit_pillai@demogmail.com | F7: 1564139537 | G7: radhika_jadhav@demooutlook.com | H7: 2242388496
A8: 201 | B8: Abhishek Srivastava | C8: Abhishek Srivastava | D8: Owner | E8: abhishek_srivastava@demogmail.com | F8: 2101226916 | G8: abhishek_srivastava@demogmail.com | H8: 2101226916
A9: 202 | B9: Reyansh Narang | C9: Parth Chatterjee | D9: Rental | E9: reyansh_narang@demoyahoo.com | F9: 1184514627 | G9: parth_chatterjee@demogmail.com | H9: 2828148932
A10: 203 | B10: Ayaan Khanna | C10: Ayaan Khanna | D10: Owner | E10: ayaan_khanna@demoyahoo.com | F10: 1957015430 | G10: ayaan_khanna@demoyahoo.com | H10: 1957015430
A11: 204 | B11: Nikhil Purohit | C11: Rohan Fernandes | D11: Rental | E11: nikhil_purohit@demogmail.com | F11: 1278248963 | G11: rohan_fernandes@demoyahoo.com | H11: 1465787133
A12: 205 | B12: Krishna Reddy | C12: Krishna Reddy | D12: Owner | E12: krishna_reddy@demoyahoo.com | F12: 1930103105 | G12: krishna_reddy@demoyahoo.com | H12: 1930103105
A13: 206 | B13: Krishna Bhat | C13: Krishna Bhat | D13: Owner | E13: krishna_bhat@demoyahoo.com | F13: 2382997376 | G13: krishna_bhat@demoyahoo.com | H13: 2382997376
... A109: 1806 | B109: Ananya Chaudhary | C109: Nandini Nair | D109: Rental | E109: ananya_chaudhary@demoyahoo.com | F109: 2188442258 | G109: nandini_nair@demogmail.com | H109: 1323705895

Sheet Maintenance Charges
A1: Flat No. | B1: Owner Name | C1: Resident Name | D1: Occupancy Type | E1: Owner Email | F1: Owner Mobile | G1: Resident Email | H1: Resident Mobile | I1: Jan-26 | J1: Feb-26 | K1: Mar-26 | L1: Apr-26 | M1: May-26 | N1: Jun-26 | O1: Jul-26 | P1: Aug-26 | Q1: Sep-26 | R1: Oct-26 | S1: Nov-26 | T1: Dec-26
A2: 101 | B2: Meera Bhatt | C2: Meera Bhatt | D2: Owner | E2: meera_bhatt@demooutlook.com | F2: 1321819600 | G2: meera_bhatt@demooutlook.com | H2: 1321819600 | I2: 3500 | J2: 3500 | K2: 3500 | L2: 3500 | M2: 3500 | N2: 3500 | O2: 3500 | P2: 3500 | Q2: 3500 | R2: 3500 | S2: 3500 | T2: 3500
A3: 102 | B3: Rohan Gill | C3: Rohan Gill | D3: Owner | E3: rohan_gill@demoyahoo.com | F3: 1838637940 | G3: rohan_gill@demoyahoo.com | H3: 1838637940 | I3: 3500 | J3: 3500 | K3: 3500 | L3: 3500 | M3: 3500 | N3: 3500 | O3: 3500 | P3: 3500 | Q3: 3500 | R3: 3500 | S3: 3500 | T3: 3500
A4: 103 | B4: Mansi Khanna | C4: Mansi Khanna | D4: Owner | E4: mansi_khanna@demooutlook.com | F4: 2235116155 | G4: mansi_khanna@demooutlook.com | H4: 2235116155 | I4: 3500 | J4: 3500 | K4: 3500 | L4: 3500 | M4: 3500 | N4: 3500 | O4: 3500 | P4: 3500 | Q4: 3500 | R4: 3500 | S4: 3500 | T4: 3500
A5: 104 | B5: Manish Mukherjee | C5: Shreya Sisodia | D5: Rental | E5: manish_mukherjee@demoyahoo.com | F5: 1618495931 | G5: shreya_sisodia@demogmail.com | H5: 1413164752 | I5: 3500 | J5: 3500 | K5: 3500 | L5: 3500 | M5: 3500 | N5: 3500 | O5: 3500 | P5: 3500 | Q5: 3500 | R5: 3500 | S5: 3500 | T5: 3500
A6: 105 | B6: Ayaan Naidu | C6: Ayaan Naidu | D6: Owner | E6: ayaan_naidu@demooutlook.com | F6: 1928327648 | G6: ayaan_naidu@demooutlook.com | H6: 1928327648 | I6: 3500 | J6: 3500 | K6: 3500 | L6: 3500 | M6: 3500 | N6: 3500 | O6: 3500 | P6: 3500 | Q6: 3500 | R6: 3500 | S6: 3500 | T6: 3500
A7: 106 | B7: Ankit Pillai | C7: Radhika Jadhav | D7: Rental | E7: ankit_pillai@demogmail.com | F7: 1564139537 | G7: radhika_jadhav@demooutlook.com | H7: 2242388496 | I7: 3500 | J7: 3500 | K7: 3500 | L7: 3500 | M7: 3500 | N7: 3500 | O7: 3500 | P7: 3500 | Q7: 3500 | R7: 3500 | S7: 3500 | T7: 3500
A8: 201 | B8: Abhishek Srivastava | C8: Abhishek Srivastava | D8: Owner | E8: abhishek_srivastava@demogmail.com | F8: 2101226916 | G8: abhishek_srivastava@demogmail.com | H8: 2101226916 | I8: 3500 | J8: 3500 | K8: 3500 | L8: 3500 | M8: 3500 | N8: 3500 | O8: 3500 | P8: 3500 | Q8: 3500 | R8: 3500 | S8: 3500 | T8: 3500
A9: 202 | B9: Reyansh Narang | C9: Parth Chatterjee | D9: Rental | E9: reyansh_narang@demoyahoo.com | F9: 1184514627 | G9: parth_chatterjee@demogmail.com | H9: 2828148932 | I9: 3500 | J9: 3500 | K9: 3500 | L9: 3500 | M9: 3500 | N9: 3500 | O9: 3500 | P9: 3500 | Q9: 3500 | R9: 3500 | S9: 3500 | T9: 3500
A10: 203 | B10: Ayaan Khanna | C10: Ayaan Khanna | D10: Owner | E10: ayaan_khanna@demoyahoo.com | F10: 1957015430 | G10: ayaan_khanna@demoyahoo.com | H10: 1957015430 | I10: 3500 | J10: 3500 | K10: 3500 | L10: 3500 | M10: 3500 | N10: 3500 | O10: 3500 | P10: 3500 | Q10: 3500 | R10: 3500 | S10: 3500 | T10: 3500
A11: 204 | B11: Nikhil Purohit | C11: Rohan Fernandes | D11: Rental | E11: nikhil_purohit@demogmail.com | F11: 1278248963 | G11: rohan_fernandes@demoyahoo.com | H11: 1465787133 | I11: 3500 | J11: 3500 | K11: 3500 | L11: 3500 | M11: 3500 | N11: 3500 | O11: 3500 | P11: 3500 | Q11: 3500 | R11: 3500 | S11: 3500 | T11: 3500
A12: 205 | B12: Krishna Reddy | C12: Krishna Reddy | D12: Owner | E12: krishna_reddy@demoyahoo.com | F12: 1930103105 | G12: krishna_reddy@demoyahoo.com | H12: 1930103105 | I12: 3500 | J12: 3500 | K12: 3500 | L12: 3500 | M12: 3500 | N12: 3500 | O12: 3500 | P12: 3500 | Q12: 3500 | R12: 3500 | S12: 3500 | T12: 3500
A13: 206 | B13: Krishna Bhat | C13: Krishna Bhat | D13: Owner | E13: krishna_bhat@demoyahoo.com | F13: 2382997376 | G13: krishna_bhat@demoyahoo.com | H13: 2382997376 | I13: 3500 | J13: 3500 | K13: 3500 | L13: 3500 | M13: 3500 | N13: 3500 | O13: 3500 | P13: 3500 | Q13: 3500 | R13: 3500 | S13: 3500 | T13: 3500
... A109: 1806 | B109: Ananya Chaudhary | C109: Nandini Nair | D109: Rental | E109: ananya_chaudhary@demoyahoo.com | F109: 2188442258 | G109: nandini_nair@demogmail.com | H109: 1323705895 | I109: 3500 | J109: 3500 | K109: 3500 | L109: 3500 | M109: 3500 | N109: 3500 | O109: 3500 | P109: 3500 | Q109: 3500 | R109: 3500 | S109: 3500 | T109: 3500

Sheet Parking Violation Fines
A1: Flat No. | B1: Owner Name | C1: Resident Name | D1: Occupancy Type | E1: Owner Email | F1: Owner Mobile | G1: Resident Email | H1: Resident Mobile | I1: Jan-26 | J1: Feb-26 | K1: Mar-26 | L1: Apr-26 | M1: May-26 | N1: Jun-26 | O1: Jul-26 | P1: Aug-26 | Q1: Sep-26 | R1: Oct-26 | S1: Nov-26 | T1: Dec-26
A2: 101 | B2: Meera Bhatt | C2: Meera Bhatt | D2: Owner | E2: meera_bhatt@demooutlook.com | F2: 1321819600 | G2: meera_bhatt@demooutlook.com | H2: 1321819600 | I2: 0 | J2: 0 | K2: 0 | L2: 0 | M2: 0 | N2: 0 | O2: 0 | P2: 0 | Q2: 0 | R2: 0 | S2: 0 | T2: 0
A3: 102 | B3: Rohan Gill | C3: Rohan Gill | D3: Owner | E3: rohan_gill@demoyahoo.com | F3: 1838637940 | G3: rohan_gill@demoyahoo.com | H3: 1838637940 | I3: 0 | J3: 0 | K3: 0 | L3: 0 | M3: 0 | N3: 0 | O3: 0 | P3: 0 | Q3: 0 | R3: 0 | S3: 0 | T3: 0
A4: 103 | B4: Mansi Khanna | C4: Mansi Khanna | D4: Owner | E4: mansi_khanna@demooutlook.com | F4: 2235116155 | G4: mansi_khanna@demooutlook.com | H4: 2235116155 | I4: 0 | J4: 0 | K4: 0 | L4: 0 | M4: 0 | N4: 0 | O4: 0 | P4: 0 | Q4: 0 | R4: 0 | S4: 0 | T4: 0
A5: 104 | B5: Manish Mukherjee | C5: Shreya Sisodia | D5: Rental | E5: manish_mukherjee@demoyahoo.com | F5: 1618495931 | G5: shreya_sisodia@demogmail.com | H5: 1413164752 | I5: 0 | J5: 0 | K5: 500 | L5: 0 | M5: 0 | N5: 0 | O5: 0 | P5: 0 | Q5: 0 | R5: 0 | S5: 0 | T5: 0
A6: 105 | B6: Ayaan Naidu | C6: Ayaan Naidu | D6: Owner | E6: ayaan_naidu@demooutlook.com | F6: 1928327648 | G6: ayaan_naidu@demooutlook.com | H6: 1928327648 | I6: 0 | J6: 0 | K6: 0 | L6: 0 | M6: 0 | N6: 0 | O6: 0 | P6: 0 | Q6: 0 | R6: 0 | S6: 0 | T6: 0
A7: 106 | B7: Ankit Pillai | C7: Radhika Jadhav | D7: Rental | E7: ankit_pillai@demogmail.com | F7: 1564139537 | G7: radhika_jadhav@demooutlook.com | H7: 2242388496 | I7: 0 | J7: 0 | K7: 0 | L7: 0 | M7: 0 | N7: 0 | O7: 0 | P7: 0 | Q7: 0 | R7: 0 | S7: 0 | T7: 0
A8: 201 | B8: Abhishek Srivastava | C8: Abhishek Srivastava | D8: Owner | E8: abhishek_srivastava@demogmail.com | F8: 2101226916 | G8: abhishek_srivastava@demogmail.com | H8: 2101226916 | I8: 0 | J8: 0 | K8: 0 | L8: 0 | M8: 0 | N8: 0 | O8: 0 | P8: 0 | Q8: 0 | R8: 0 | S8: 0 | T8: 0
A9: 202 | B9: Reyansh Narang | C9: Parth Chatterjee | D9: Rental | E9: reyansh_narang@demoyahoo.com | F9: 1184514627 | G9: parth_chatterjee@demogmail.com | H9: 2828148932 | I9: 0 | J9: 0 | K9: 0 | L9: 0 | M9: 0 | N9: 0 | O9: 0 | P9: 0 | Q9: 0 | R9: 0 | S9: 0 | T9: 0
A10: 203 | B10: Ayaan Khanna | C10: Ayaan Khanna | D10: Owner | E10: ayaan_khanna@demoyahoo.com | F10: 1957015430 | G10: ayaan_khanna@demoyahoo.com | H10: 1957015430 | I10: 0 | J10: 0 | K10: 0 | L10: 0 | M10: 0 | N10: 0 | O10: 0 | P10: 0 | Q10: 0 | R10: 0 | S10: 0 | T10: 0
A11: 204 | B11: Nikhil Purohit | C11: Rohan Fernandes | D11: Rental | E11: nikhil_purohit@demogmail.com | F11: 1278248963 | G11: rohan_fernandes@demoyahoo.com | H11: 1465787133 | I11: 0 | J11: 0 | K11: 0 | L11: 0 | M11: 0 | N11: 0 | O11: 0 | P11: 0 | Q11: 0 | R11: 0 | S11: 0 | T11: 0
A12: 205 | B12: Krishna Reddy | C12: Krishna Reddy | D12: Owner | E12: krishna_reddy@demoyahoo.com | F12: 1930103105 | G12: krishna_reddy@demoyahoo.com | H12: 1930103105 | I12: 0 | J12: 0 | K12: 0 | L12: 0 | M12: 0 | N12: 0 | O12: 0 | P12: 0 | Q12: 0 | R12: 0 | S12: 0 | T12: 0
A13: 206 | B13: Krishna Bhat | C13: Krishna Bhat | D13: Owner | E13: krishna_bhat@demoyahoo.com | F13: 2382997376 | G13: krishna_bhat@demoyahoo.com | H13: 2382997376 | I13: 0 | J13: 0 | K13: 0 | L13: 0 | M13: 0 | N13: 0 | O13: 0 | P13: 0 | Q13: 0 | R13: 0 | S13: 0 | T13: 0
... A109: 1806 | B109: Ananya Chaudhary | C109: Nandini Nair | D109: Rental | E109: ananya_chaudhary@demoyahoo.com | F109: 2188442258 | G109: nandini_nair@demogmail.com | H109: 1323705895 | I109: 0 | J109: 0 | K109: 0 | L109: 0 | M109: 0 | N109: 0 | O109: 0 | P109: 0 | Q109: 0 | R109: 0 | S109: 0 | T109: 0

Sheet Waste Management Fines
A1: Flat No. | B1: Owner Name | C1: Resident Name | D1: Occupancy Type | E1: Owner Email | F1: Owner Mobile | G1: Resident Email | H1: Resident Mobile | I1: Jan-26 | J1: Feb-26 | K1: Mar-26 | L1: Apr-26 | M1: May-26 | N1: Jun-26 | O1: Jul-26 | P1: Aug-26 | Q1: Sep-26 | R1: Oct-26 | S1: Nov-26 | T1: Dec-26
A2: 101 | B2: Meera Bhatt | C2: Meera Bhatt | D2: Owner | E2: meera_bhatt@demooutlook.com | F2: 1321819600 | G2: meera_bhatt@demooutlook.com | H2: 1321819600 | I2: 0 | J2: 0 | K2: 0 | L2: 0 | M2: 0 | N2: 0 | O2: 0 | P2: 0 | Q2: 0 | R2: 0 | S2: 0 | T2: 0
A3: 102 | B3: Rohan Gill | C3: Rohan Gill | D3: Owner | E3: rohan_gill@demoyahoo.com | F3: 1838637940 | G3: rohan_gill@demoyahoo.com | H3: 1838637940 | I3: 0 | J3: 0 | K3: 0 | L3: 0 | M3: 0 | N3: 0 | O3: 0 | P3: 0 | Q3: 0 | R3: 0 | S3: 0 | T3: 0
A4: 103 | B4: Mansi Khanna | C4: Mansi Khanna | D4: Owner | E4: mansi_khanna@demooutlook.com | F4: 2235116155 | G4: mansi_khanna@demooutlook.com | H4: 2235116155 | I4: 0 | J4: 0 | K4: 0 | L4: 0 | M4: 0 | N4: 0 | O4: 0 | P4: 0 | Q4: 0 | R4: 0 | S4: 0 | T4: 0
A5: 104 | B5: Manish Mukherjee | C5: Shreya Sisodia | D5: Rental | E5: manish_mukherjee@demoyahoo.com | F5: 1618495931 | G5: shreya_sisodia@demogmail.com | H5: 1413164752 | I5: 0 | J5: 0 | K5: 0 | L5: 0 | M5: 0 | N5: 0 | O5: 0 | P5: 0 | Q5: 0 | R5: 0 | S5: 0 | T5: 0
A6: 105 | B6: Ayaan Naidu | C6: Ayaan Naidu | D6: Owner | E6: ayaan_naidu@demooutlook.com | F6: 1928327648 | G6: ayaan_naidu@demooutlook.com | H6: 1928327648 | I6: 0 | J6: 0 | K6: 0 | L6: 0 | M6: 0 | N6: 0 | O6: 0 | P6: 0 | Q6: 0 | R6: 0 | S6: 0 | T6: 0
A7: 106 | B7: Ankit Pillai | C7: Radhika Jadhav | D7: Rental | E7: ankit_pillai@demogmail.com | F7: 1564139537 | G7: radhika_jadhav@demooutlook.com | H7: 2242388496 | I7: 0 | J7: 0 | K7: 0 | L7: 0 | M7: 0 | N7: 0 | O7: 0 | P7: 0 | Q7: 0 | R7: 0 | S7: 0 | T7: 0
A8: 201 | B8: Abhishek Srivastava | C8: Abhishek Srivastava | D8: Owner | E8: abhishek_srivastava@demogmail.com | F8: 2101226916 | G8: abhishek_srivastava@demogmail.com | H8: 2101226916 | I8: 0 | J8: 0 | K8: 0 | L8: 0 | M8: 0 | N8: 0 | O8: 0 | P8: 0 | Q8: 0 | R8: 0 | S8: 0 | T8: 0
A9: 202 | B9: Reyansh Narang | C9: Parth Chatterjee | D9: Rental | E9: reyansh_narang@demoyahoo.com | F9: 1184514627 | G9: parth_chatterjee@demogmail.com | H9: 2828148932 | I9: 0 | J9: 0 | K9: 0 | L9: 0 | M9: 0 | N9: 0 | O9: 0 | P9: 0 | Q9: 0 | R9: 0 | S9: 0 | T9: 0
A10: 203 | B10: Ayaan Khanna | C10: Ayaan Khanna | D10: Owner | E10: ayaan_khanna@demoyahoo.com | F10: 1957015430 | G10: ayaan_khanna@demoyahoo.com | H10: 1957015430 | I10: 0 | J10: 0 | K10: 0 | L10: 0 | M10: 0 | N10: 0 | O10: 0 | P10: 0 | Q10: 0 | R10: 0 | S10: 0 | T10: 0
A11: 204 | B11: Nikhil Purohit | C11: Rohan Fernandes | D11: Rental | E11: nikhil_purohit@demogmail.com | F11: 1278248963 | G11: rohan_fernandes@demoyahoo.com | H11: 1465787133 | I11: 0 | J11: 0 | K11: 0 | L11: 0 | M11: 0 | N11: 0 | O11: 0 | P11: 0 | Q11: 0 | R11: 0 | S11: 0 | T11: 0
A12: 205 | B12: Krishna Reddy | C12: Krishna Reddy | D12: Owner | E12: krishna_reddy@demoyahoo.com | F12: 1930103105 | G12: krishna_reddy@demoyahoo.com | H12: 1930103105 | I12: 0 | J12: 0 | K12: 0 | L12: 0 | M12: 0 | N12: 0 | O12: 0 | P12: 0 | Q12: 0 | R12: 0 | S12: 0 | T12: 0
A13: 206 | B13: Krishna Bhat | C13: Krishna Bhat | D13: Owner | E13: krishna_bhat@demoyahoo.com | F13: 2382997376 | G13: krishna_bhat@demoyahoo.com | H13: 2382997376 | I13: 0 | J13: 0 | K13: 0 | L13: 0 | M13: 0 | N13: 0 | O13: 0 | P13: 0 | Q13: 0 | R13: 0 | S13: 0 | T13: 0
... A109: 1806 | B109: Ananya Chaudhary | C109: Nandini Nair | D109: Rental | E109: ananya_chaudhary@demoyahoo.com | F109: 2188442258 | G109: nandini_nair@demogmail.com | H109: 1323705895 | I109: 0 | J109: 0 | K109: 0 | L109: 0 | M109: 0 | N109: 0 | O109: 0 | P109: 0 | Q109: 0 | R109: 0 | S109: 0 | T109: 0

Sheet Pet Policy Fines
A1: Flat No. | B1: Owner Name | C1: Resident Name | D1: Occupancy Type | E1: Owner Email | F1: Owner Mobile | G1: Resident Email | H1: Resident Mobile | I1: Jan-26 | J1: Feb-26 | K1: Mar-26 | L1: Apr-26 | M1: May-26 | N1: Jun-26 | O1: Jul-26 | P1: Aug-26 | Q1: Sep-26 | R1: Oct-26 | S1: Nov-26 | T1: Dec-26
A2: 101 | B2: Meera Bhatt | C2: Meera Bhatt | D2: Owner | E2: meera_bhatt@demooutlook.com | F2: 1321819600 | G2: meera_bhatt@demooutlook.com | H2: 1321819600 | I2: 0 | J2: 0 | K2: 0 | L2: 0 | M2: 0 | N2: 0 | O2: 0 | P2: 0 | Q2: 0 | R2: 0 | S2: 0 | T2: 0
A3: 102 | B3: Rohan Gill | C3: Rohan Gill | D3: Owner | E3: rohan_gill@demoyahoo.com | F3: 1838637940 | G3: rohan_gill@demoyahoo.com | H3: 1838637940 | I3: 0 | J3: 0 | K3: 0 | L3: 0 | M3: 0 | N3: 0 | O3: 0 | P3: 0 | Q3: 0 | R3: 0 | S3: 0 | T3: 0
A4: 103 | B4: Mansi Khanna | C4: Mansi Khanna | D4: Owner | E4: mansi_khanna@demooutlook.com | F4: 2235116155 | G4: mansi_khanna@demooutlook.com | H4: 2235116155 | I4: 0 | J4: 0 | K4: 0 | L4: 0 | M4: 0 | N4: 0 | O4: 0 | P4: 0 | Q4: 0 | R4: 0 | S4: 0 | T4: 0
A5: 104 | B5: Manish Mukherjee | C5: Shreya Sisodia | D5: Rental | E5: manish_mukherjee@demoyahoo.com | F5: 1618495931 | G5: shreya_sisodia@demogmail.com | H5: 1413164752 | I5: 0 | J5: 0 | K5: 0 | L5: 0 | M5: 0 | N5: 0 | O5: 0 | P5: 0 | Q5: 0 | R5: 0 | S5: 0 | T5: 0
A6: 105 | B6: Ayaan Naidu | C6: Ayaan Naidu | D6: Owner | E6: ayaan_naidu@demooutlook.com | F6: 1928327648 | G6: ayaan_naidu@demooutlook.com | H6: 1928327648 | I6: 0 | J6: 0 | K6: 0 | L6: 0 | M6: 0 | N6: 0 | O6: 0 | P6: 0 | Q6: 0 | R6: 0 | S6: 0 | T6: 0
A7: 106 | B7: Ankit Pillai | C7: Radhika Jadhav | D7: Rental | E7: ankit_pillai@demogmail.com | F7: 1564139537 | G7: radhika_jadhav@demooutlook.com | H7: 2242388496 | I7: 0 | J7: 0 | K7: 0 | L7: 0 | M7: 0 | N7: 0 | O7: 0 | P7: 0 | Q7: 0 | R7: 0 | S7: 0 | T7: 0
A8: 201 | B8: Abhishek Srivastava | C8: Abhishek Srivastava | D8: Owner | E8: abhishek_srivastava@demogmail.com | F8: 2101226916 | G8: abhishek_srivastava@demogmail.com | H8: 2101226916 | I8: 0 | J8: 0 | K8: 0 | L8: 0 | M8: 0 | N8: 0 | O8: 0 | P8: 0 | Q8: 0 | R8: 0 | S8: 0 | T8: 0
A9: 202 | B9: Reyansh Narang | C9: Parth Chatterjee | D9: Rental | E9: reyansh_narang@demoyahoo.com | F9: 1184514627 | G9: parth_chatterjee@demogmail.com | H9: 2828148932 | I9: 0 | J9: 0 | K9: 0 | L9: 0 | M9: 0 | N9: 0 | O9: 0 | P9: 0 | Q9: 0 | R9: 0 | S9: 0 | T9: 0
A10: 203 | B10: Ayaan Khanna | C10: Ayaan Khanna | D10: Owner | E10: ayaan_khanna@demoyahoo.com | F10: 1957015430 | G10: ayaan_khanna@demoyahoo.com | H10: 1957015430 | I10: 0 | J10: 0 | K10: 0 | L10: 0 | M10: 0 | N10: 0 | O10: 0 | P10: 0 | Q10: 0 | R10: 0 | S10: 0 | T10: 0
A11: 204 | B11: Nikhil Purohit | C11: Rohan Fernandes | D11: Rental | E11: nikhil_purohit@demogmail.com | F11: 1278248963 | G11: rohan_fernandes@demoyahoo.com | H11: 1465787133 | I11: 0 | J11: 0 | K11: 0 | L11: 0 | M11: 0 | N11: 0 | O11: 0 | P11: 0 | Q11: 0 | R11: 0 | S11: 0 | T11: 0
A12: 205 | B12: Krishna Reddy | C12: Krishna Reddy | D12: Owner | E12: krishna_reddy@demoyahoo.com | F12: 1930103105 | G12: krishna_reddy@demoyahoo.com | H12: 1930103105 | I12: 0 | J12: 0 | K12: 0 | L12: 0 | M12: 0 | N12: 0 | O12: 0 | P12: 0 | Q12: 0 | R12: 0 | S12: 0 | T12: 0
A13: 206 | B13: Krishna Bhat | C13: Krishna Bhat | D13: Owner | E13: krishna_bhat@demoyahoo.com | F13: 2382997376 | G13: krishna_bhat@demoyahoo.com | H13: 2382997376 | I13: 0 | J13: 0 | K13: 0 | L13: 0 | M13: 0 | N13: 0 | O13: 0 | P13: 0 | Q13: 0 | R13: 0 | S13: 0 | T13: 0
... A109: 1806 | B109: Ananya Chaudhary | C109: Nandini Nair | D109: Rental | E109: ananya_chaudhary@demoyahoo.com | F109: 2188442258 | G109: nandini_nair@demogmail.com | H109: 1323705895 | I109: 0 | J109: 0 | K109: 0 | L109: 0 | M109: 0 | N109: 0 | O109: 0 | P109: 0 | Q109: 0 | R109: 0 | S109: 0 | T109: 0

Sheet Noise Violation Fines
A1: Flat No. | B1: Owner Name | C1: Resident Name | D1: Occupancy Type | E1: Owner Email | F1: Owner Mobile | G1: Resident Email | H1: Resident Mobile | I1: Jan-26 | J1: Feb-26 | K1: Mar-26 | L1: Apr-26 | M1: May-26 | N1: Jun-26 | O1: Jul-26 | P1: Aug-26 | Q1: Sep-26 | R1: Oct-26 | S1: Nov-26 | T1: Dec-26
A2: 101 | B2: Meera Bhatt | C2: Meera Bhatt | D2: Owner | E2: meera_bhatt@demooutlook.com | F2: 1321819600 | G2: meera_bhatt@demooutlook.com | H2: 1321819600 | I2: 0 | J2: 0 | K2: 0 | L2: 0 | M2: 0 | N2: 0 | O2: 0 | P2: 0 | Q2: 0 | R2: 0 | S2: 0 | T2: 0
A3: 102 | B3: Rohan Gill | C3: Rohan Gill | D3: Owner | E3: rohan_gill@demoyahoo.com | F3: 1838637940 | G3: rohan_gill@demoyahoo.com | H3: 1838637940 | I3: 0 | J3: 0 | K3: 0 | L3: 0 | M3: 0 | N3: 0 | O3: 0 | P3: 0 | Q3: 0 | R3: 0 | S3: 0 | T3: 0
A4: 103 | B4: Mansi Khanna | C4: Mansi Khanna | D4: Owner | E4: mansi_khanna@demooutlook.com | F4: 2235116155 | G4: mansi_khanna@demooutlook.com | H4: 2235116155 | I4: 0 | J4: 0 | K4: 0 | L4: 0 | M4: 0 | N4: 0 | O4: 0 | P4: 0 | Q4: 0 | R4: 0 | S4: 0 | T4: 0
A5: 104 | B5: Manish Mukherjee | C5: Shreya Sisodia | D5: Rental | E5: manish_mukherjee@demoyahoo.com | F5: 1618495931 | G5: shreya_sisodia@demogmail.com | H5: 1413164752 | I5: 0 | J5: 0 | K5: 0 | L5: 300 | M5: 0 | N5: 0 | O5: 0 | P5: 0 | Q5: 0 | R5: 0 | S5: 0 | T5: 0
A6: 105 | B6: Ayaan Naidu | C6: Ayaan Naidu | D6: Owner | E6: ayaan_naidu@demooutlook.com | F6: 1928327648 | G6: ayaan_naidu@demooutlook.com | H6: 1928327648 | I6: 0 | J6: 0 | K6: 0 | L6: 0 | M6: 0 | N6: 0 | O6: 0 | P6: 0 | Q6: 0 | R6: 0 | S6: 0 | T6: 0
A7: 106 | B7: Ankit Pillai | C7: Radhika Jadhav | D7: Rental | E7: ankit_pillai@demogmail.com | F7: 1564139537 | G7: radhika_jadhav@demooutlook.com | H7: 2242388496 | I7: 0 | J7: 0 | K7: 0 | L7: 0 | M7: 0 | N7: 0 | O7: 0 | P7: 0 | Q7: 0 | R7: 0 | S7: 0 | T7: 0
A8: 201 | B8: Abhishek Srivastava | C8: Abhishek Srivastava | D8: Owner | E8: abhishek_srivastava@demogmail.com | F8: 2101226916 | G8: abhishek_srivastava@demogmail.com | H8: 2101226916 | I8: 0 | J8: 0 | K8: 0 | L8: 0 | M8: 0 | N8: 0 | O8: 0 | P8: 0 | Q8: 0 | R8: 0 | S8: 0 | T8: 0
A9: 202 | B9: Reyansh Narang | C9: Parth Chatterjee | D9: Rental | E9: reyansh_narang@demoyahoo.com | F9: 1184514627 | G9: parth_chatterjee@demogmail.com | H9: 2828148932 | I9: 0 | J9: 0 | K9: 0 | L9: 0 | M9: 0 | N9: 0 | O9: 0 | P9: 0 | Q9: 0 | R9: 0 | S9: 0 | T9: 0
A10: 203 | B10: Ayaan Khanna | C10: Ayaan Khanna | D10: Owner | E10: ayaan_khanna@demoyahoo.com | F10: 1957015430 | G10: ayaan_khanna@demoyahoo.com | H10: 1957015430 | I10: 0 | J10: 0 | K10: 0 | L10: 0 | M10: 0 | N10: 0 | O10: 0 | P10: 0 | Q10: 0 | R10: 0 | S10: 0 | T10: 0
A11: 204 | B11: Nikhil Purohit | C11: Rohan Fernandes | D11: Rental | E11: nikhil_purohit@demogmail.com | F11: 1278248963 | G11: rohan_fernandes@demoyahoo.com | H11: 1465787133 | I11: 0 | J11: 0 | K11: 0 | L11: 0 | M11: 0 | N11: 0 | O11: 0 | P11: 0 | Q11: 0 | R11: 0 | S11: 0 | T11: 0
A12: 205 | B12: Krishna Reddy | C12: Krishna Reddy | D12: Owner | E12: krishna_reddy@demoyahoo.com | F12: 1930103105 | G12: krishna_reddy@demoyahoo.com | H12: 1930103105 | I12: 0 | J12: 0 | K12: 0 | L12: 0 | M12: 0 | N12: 0 | O12: 0 | P12: 0 | Q12: 0 | R12: 0 | S12: 0 | T12: 0
A13: 206 | B13: Krishna Bhat | C13: Krishna Bhat | D13: Owner | E13: krishna_bhat@demoyahoo.com | F13: 2382997376 | G13: krishna_bhat@demoyahoo.com | H13: 2382997376 | I13: 0 | J13: 0 | K13: 0 | L13: 0 | M13: 0 | N13: 0 | O13: 0 | P13: 0 | Q13: 0 | R13: 0 | S13: 0 | T13: 0
... A109: 1806 | B109: Ananya Chaudhary | C109: Nandini Nair | D109: Rental | E109: ananya_chaudhary@demoyahoo.com | F109: 2188442258 | G109: nandini_nair@demogmail.com | H109: 1323705895 | I109: 0 | J109: 0 | K109: 0 | L109: 0 | M109: 0 | N109: 0 | O109: 0 | P109: 0 | Q109: 0 | R109: 0 | S109: 0 | T109: 0

Sheet Property Damage Fines
A1: Flat No. | B1: Owner Name | C1: Resident Name | D1: Occupancy Type | E1: Owner Email | F1: Owner Mobile | G1: Resident Email | H1: Resident Mobile | I1: Jan-26 | J1: Feb-26 | K1: Mar-26 | L1: Apr-26 | M1: May-26 | N1: Jun-26 | O1: Jul-26 | P1: Aug-26 | Q1: Sep-26 | R1: Oct-26 | S1: Nov-26 | T1: Dec-26
A2: 101 | B2: Meera Bhatt | C2: Meera Bhatt | D2: Owner | E2: meera_bhatt@demooutlook.com | F2: 1321819600 | G2: meera_bhatt@demooutlook.com | H2: 1321819600 | I2: 0 | J2: 0 | K2: 0 | L2: 0 | M2: 0 | N2: 0 | O2: 0 | P2: 0 | Q2: 0 | R2: 0 | S2: 0 | T2: 0
A3: 102 | B3: Rohan Gill | C3: Rohan Gill | D3: Owner | E3: rohan_gill@demoyahoo.com | F3: 1838637940 | G3: rohan_gill@demoyahoo.com | H3: 1838637940 | I3: 0 | J3: 0 | K3: 0 | L3: 0 | M3: 0 | N3: 0 | O3: 0 | P3: 0 | Q3: 0 | R3: 0 | S3: 0 | T3: 0
A4: 103 | B4: Mansi Khanna | C4: Mansi Khanna | D4: Owner | E4: mansi_khanna@demooutlook.com | F4: 2235116155 | G4: mansi_khanna@demooutlook.com | H4: 2235116155 | I4: 0 | J4: 0 | K4: 0 | L4: 0 | M4: 0 | N4: 0 | O4: 0 | P4: 0 | Q4: 0 | R4: 0 | S4: 0 | T4: 0
A5: 104 | B5: Manish Mukherjee | C5: Shreya Sisodia | D5: Rental | E5: manish_mukherjee@demoyahoo.com | F5: 1618495931 | G5: shreya_sisodia@demogmail.com | H5: 1413164752 | I5: 0 | J5: 0 | K5: 0 | L5: 0 | M5: 0 | N5: 0 | O5: 0 | P5: 0 | Q5: 0 | R5: 0 | S5: 0 | T5: 0
A6: 105 | B6: Ayaan Naidu | C6: Ayaan Naidu | D6: Owner | E6: ayaan_naidu@demooutlook.com | F6: 1928327648 | G6: ayaan_naidu@demooutlook.com | H6: 1928327648 | I6: 0 | J6: 0 | K6: 0 | L6: 0 | M6: 0 | N6: 0 | O6: 0 | P6: 0 | Q6: 0 | R6: 0 | S6: 0 | T6: 0
A7: 106 | B7: Ankit Pillai | C7: Radhika Jadhav | D7: Rental | E7: ankit_pillai@demogmail.com | F7: 1564139537 | G7: radhika_jadhav@demooutlook.com | H7: 2242388496 | I7: 0 | J7: 0 | K7: 0 | L7: 0 | M7: 0 | N7: 0 | O7: 0 | P7: 0 | Q7: 0 | R7: 0 | S7: 0 | T7: 0
A8: 201 | B8: Abhishek Srivastava | C8: Abhishek Srivastava | D8: Owner | E8: abhishek_srivastava@demogmail.com | F8: 2101226916 | G8: abhishek_srivastava@demogmail.com | H8: 2101226916 | I8: 0 | J8: 0 | K8: 0 | L8: 0 | M8: 0 | N8: 0 | O8: 0 | P8: 0 | Q8: 0 | R8: 0 | S8: 0 | T8: 0
A9: 202 | B9: Reyansh Narang | C9: Parth Chatterjee | D9: Rental | E9: reyansh_narang@demoyahoo.com | F9: 1184514627 | G9: parth_chatterjee@demogmail.com | H9: 2828148932 | I9: 0 | J9: 0 | K9: 0 | L9: 0 | M9: 0 | N9: 0 | O9: 0 | P9: 0 | Q9: 0 | R9: 0 | S9: 0 | T9: 0
A10: 203 | B10: Ayaan Khanna | C10: Ayaan Khanna | D10: Owner | E10: ayaan_khanna@demoyahoo.com | F10: 1957015430 | G10: ayaan_khanna@demoyahoo.com | H10: 1957015430 | I10: 0 | J10: 0 | K10: 0 | L10: 0 | M10: 0 | N10: 0 | O10: 0 | P10: 0 | Q10: 0 | R10: 0 | S10: 0 | T10: 0
A11: 204 | B11: Nikhil Purohit | C11: Rohan Fernandes | D11: Rental | E11: nikhil_purohit@demogmail.com | F11: 1278248963 | G11: rohan_fernandes@demoyahoo.com | H11: 1465787133 | I11: 0 | J11: 0 | K11: 0 | L11: 0 | M11: 0 | N11: 0 | O11: 0 | P11: 0 | Q11: 0 | R11: 0 | S11: 0 | T11: 0
A12: 205 | B12: Krishna Reddy | C12: Krishna Reddy | D12: Owner | E12: krishna_reddy@demoyahoo.com | F12: 1930103105 | G12: krishna_reddy@demoyahoo.com | H12: 1930103105 | I12: 0 | J12: 0 | K12: 0 | L12: 0 | M12: 0 | N12: 0 | O12: 0 | P12: 0 | Q12: 0 | R12: 0 | S12: 0 | T12: 0
A13: 206 | B13: Krishna Bhat | C13: Krishna Bhat | D13: Owner | E13: krishna_bhat@demoyahoo.com | F13: 2382997376 | G13: krishna_bhat@demoyahoo.com | H13: 2382997376 | I13: 0 | J13: 0 | K13: 0 | L13: 0 | M13: 0 | N13: 0 | O13: 0 | P13: 0 | Q13: 0 | R13: 0 | S13: 0 | T13: 0
... A109: 1806 | B109: Ananya Chaudhary | C109: Nandini Nair | D109: Rental | E109: ananya_chaudhary@demoyahoo.com | F109: 2188442258 | G109: nandini_nair@demogmail.com | H109: 1323705895 | I109: 0 | J109: 0 | K109: 0 | L109: 0 | M109: 0 | N109: 0 | O109: 0 | P109: 0 | Q109: 0 | R109: 0 | S109: 0 | T109: 0

Sheet Miscellaneous Fines
A1: Flat No. | B1: Owner Name | C1: Resident Name | D1: Occupancy Type | E1: Owner Email | F1: Owner Mobile | G1: Resident Email | H1: Resident Mobile | I1: Jan-26 | J1: Feb-26 | K1: Mar-26 | L1: Apr-26 | M1: May-26 | N1: Jun-26 | O1: Jul-26 | P1: Aug-26 | Q1: Sep-26 | R1: Oct-26 | S1: Nov-26 | T1: Dec-26
A2: 101 | B2: Meera Bhatt | C2: Meera Bhatt | D2: Owner | E2: meera_bhatt@demooutlook.com | F2: 1321819600 | G2: meera_bhatt@demooutlook.com | H2: 1321819600 | I2: 0 | J2: 0 | K2: 0 | L2: 0 | M2: 0 | N2: 0 | O2: 0 | P2: 0 | Q2: 0 | R2: 0 | S2: 0 | T2: 0
A3: 102 | B3: Rohan Gill | C3: Rohan Gill | D3: Owner | E3: rohan_gill@demoyahoo.com | F3: 1838637940 | G3: rohan_gill@demoyahoo.com | H3: 1838637940 | I3: 0 | J3: 0 | K3: 0 | L3: 0 | M3: 0 | N3: 0 | O3: 0 | P3: 0 | Q3: 0 | R3: 0 | S3: 0 | T3: 0
A4: 103 | B4: Mansi Khanna | C4: Mansi Khanna | D4: Owner | E4: mansi_khanna@demooutlook.com | F4: 2235116155 | G4: mansi_khanna@demooutlook.com | H4: 2235116155 | I4: 0 | J4: 0 | K4: 0 | L4: 0 | M4: 0 | N4: 0 | O4: 0 | P4: 0 | Q4: 0 | R4: 0 | S4: 0 | T4: 0
A5: 104 | B5: Manish Mukherjee | C5: Shreya Sisodia | D5: Rental | E5: manish_mukherjee@demoyahoo.com | F5: 1618495931 | G5: shreya_sisodia@demogmail.com | H5: 1413164752 | I5: 0 | J5: 0 | K5: 0 | L5: 0 | M5: 0 | N5: 0 | O5: 0 | P5: 0 | Q5: 0 | R5: 0 | S5: 0 | T5: 0
A6: 105 | B6: Ayaan Naidu | C6: Ayaan Naidu | D6: Owner | E6: ayaan_naidu@demooutlook.com | F6: 1928327648 | G6: ayaan_naidu@demooutlook.com | H6: 1928327648 | I6: 0 | J6: 0 | K6: 0 | L6: 0 | M6: 0 | N6: 0 | O6: 0 | P6: 0 | Q6: 0 | R6: 0 | S6: 0 | T6: 0
A7: 106 | B7: Ankit Pillai | C7: Radhika Jadhav | D7: Rental | E7: ankit_pillai@demogmail.com | F7: 1564139537 | G7: radhika_jadhav@demooutlook.com | H7: 2242388496 | I7: 0 | J7: 0 | K7: 0 | L7: 0 | M7: 0 | N7: 0 | O7: 0 | P7: 0 | Q7: 0 | R7: 0 | S7: 0 | T7: 0
A8: 201 | B8: Abhishek Srivastava | C8: Abhishek Srivastava | D8: Owner | E8: abhishek_srivastava@demogmail.com | F8: 2101226916 | G8: abhishek_srivastava@demogmail.com | H8: 2101226916 | I8: 0 | J8: 0 | K8: 0 | L8: 0 | M8: 0 | N8: 0 | O8: 0 | P8: 0 | Q8: 0 | R8: 0 | S8: 0 | T8: 0
A9: 202 | B9: Reyansh Narang | C9: Parth Chatterjee | D9: Rental | E9: reyansh_narang@demoyahoo.com | F9: 1184514627 | G9: parth_chatterjee@demogmail.com | H9: 2828148932 | I9: 0 | J9: 0 | K9: 0 | L9: 0 | M9: 0 | N9: 0 | O9: 0 | P9: 0 | Q9: 0 | R9: 0 | S9: 0 | T9: 0
A10: 203 | B10: Ayaan Khanna | C10: Ayaan Khanna | D10: Owner | E10: ayaan_khanna@demoyahoo.com | F10: 1957015430 | G10: ayaan_khanna@demoyahoo.com | H10: 1957015430 | I10: 0 | J10: 0 | K10: 0 | L10: 0 | M10: 0 | N10: 0 | O10: 0 | P10: 0 | Q10: 0 | R10: 0 | S10: 0 | T10: 0
A11: 204 | B11: Nikhil Purohit | C11: Rohan Fernandes | D11: Rental | E11: nikhil_purohit@demogmail.com | F11: 1278248963 | G11: rohan_fernandes@demoyahoo.com | H11: 1465787133 | I11: 0 | J11: 0 | K11: 0 | L11: 0 | M11: 0 | N11: 0 | O11: 0 | P11: 0 | Q11: 0 | R11: 0 | S11: 0 | T11: 0
A12: 205 | B12: Krishna Reddy | C12: Krishna Reddy | D12: Owner | E12: krishna_reddy@demoyahoo.com | F12: 1930103105 | G12: krishna_reddy@demoyahoo.com | H12: 1930103105 | I12: 0 | J12: 0 | K12: 0 | L12: 0 | M12: 0 | N12: 0 | O12: 0 | P12: 0 | Q12: 0 | R12: 0 | S12: 0 | T12: 0
A13: 206 | B13: Krishna Bhat | C13: Krishna Bhat | D13: Owner | E13: krishna_bhat@demoyahoo.com | F13: 2382997376 | G13: krishna_bhat@demoyahoo.com | H13: 2382997376 | I13: 0 | J13: 0 | K13: 0 | L13: 0 | M13: 0 | N13: 0 | O13: 0 | P13: 0 | Q13: 0 | R13: 0 | S13: 0 | T13: 0
... A109: 1806 | B109: Ananya Chaudhary | C109: Nandini Nair | D109: Rental | E109: ananya_chaudhary@demoyahoo.com | F109: 2188442258 | G109: nandini_nair@demogmail.com | H109: 1323705895 | I109: 0 | J109: 0 | K109: 0 | L109: 0 | M109: 0 | N109: 0 | O109: 0 | P109: 0 | Q109: 0 | R109: 0 | S109: 0 | T109: 0

Sheet Total Charges
A1: Flat No. | B1: Owner Name | C1: Resident Name | D1: Occupancy Type | E1: Owner Email | F1: Owner Mobile | G1: Resident Email | H1: Resident Mobile | I1: Jan-26 | J1: Feb-26 | K1: Mar-26 | L1: Apr-26 | M1: May-26 | N1: Jun-26 | O1: Jul-26 | P1: Aug-26 | Q1: Sep-26 | R1: Oct-26 | S1: Nov-26 | T1: Dec-26
A2: 101 | B2: Meera Bhatt | C2: Meera Bhatt | D2: Owner | E2: meera_bhatt@demooutlook.com | F2: 1321819600 | G2: meera_bhatt@demooutlook.com | H2: 1321819600 | I2: =SUM( 'Maintenance Charges'!I2, 'Parking Violation Fines'!I2, 'Waste Management Fines'!I2, 'Pet Policy Fines'!I2, 'Noise Violation Fines'!I2, 'Property Damage Fines'!I2, 'Miscellaneous Fines'!I2 ) | J2: =SUM( 'Maintenance Charges'!J2, 'Parking Violation Fines'!J2, 'Waste Management Fines'!J2, 'Pet Policy Fines'!J2, 'Noise Violation Fines'!J2, 'Property Damage Fines'!J2, 'Miscellaneous Fines'!J2 ) | K2: =SUM( 'Maintenance Charges'!K2, 'Parking Violation Fines'!K2, 'Waste Management Fines'!K2, 'Pet Policy Fines'!K2, 'Noise Violation Fines'!K2, 'Property Damage Fines'!K2, 'Miscellaneous Fines'!K2 ) | L2: =SUM( 'Maintenance Charges'!L2, 'Parking Violation Fines'!L2, 'Waste Management Fines'!L2, 'Pet Policy Fines'!L2, 'Noise Violation Fines'!L2, 'Property Damage Fines'!L2, 'Miscellaneous Fines'!L2 ) | M2: =SUM( 'Maintenance Charges'!M2, 'Parking Violation Fines'!M2, 'Waste Management Fines'!M2, 'Pet Policy Fines'!M2, 'Noise Violation Fines'!M2, 'Property Damage Fines'!M2, 'Miscellaneous Fines'!M2 ) | N2: =SUM( 'Maintenance Charges'!N2, 'Parking Violation Fines'!N2, 'Waste Management Fines'!N2, 'Pet Policy Fines'!N2, 'Noise Violation Fines'!N2, 'Property Damage Fines'!N2, 'Miscellaneous Fines'!N2 ) | O2: =SUM( 'Maintenance Charges'!O2, 'Parking Violation Fines'!O2, 'Waste Management Fines'!O2, 'Pet Policy Fines'!O2, 'Noise Violation Fines'!O2, 'Property Damage Fines'!O2, 'Miscellaneous Fines'!O2 ) | P2: =SUM( 'Maintenance Charges'!P2, 'Parking Violation Fines'!P2, 'Waste Management Fines'!P2, 'Pet Policy Fines'!P2, 'Noise Violation Fines'!P2, 'Property Damage Fines'!P2, 'Miscellaneous Fines'!P2 ) | ... T2: =SUM( 'Maintenance Charges'!T2, 'Parking Violation Fines'!T2, 'Waste Management Fines'!T2, 'Pet Policy Fines'!T2, 'Noise Violation Fines'!T2, 'Property Damage Fines'!T2, 'Miscellaneous Fines'!T2 )
A3: 102 | B3: Rohan Gill | C3: Rohan Gill | D3: Owner | E3: rohan_gill@demoyahoo.com | F3: 1838637940 | G3: rohan_gill@demoyahoo.com | H3: 1838637940 | I3: =SUM( 'Maintenance Charges'!I3, 'Parking Violation Fines'!I3, 'Waste Management Fines'!I3, 'Pet Policy Fines'!I3, 'Noise Violation Fines'!I3, 'Property Damage Fines'!I3, 'Miscellaneous Fines'!I3 ) | J3: =SUM( 'Maintenance Charges'!J3, 'Parking Violation Fines'!J3, 'Waste Management Fines'!J3, 'Pet Policy Fines'!J3, 'Noise Violation Fines'!J3, 'Property Damage Fines'!J3, 'Miscellaneous Fines'!J3 ) | K3: =SUM( 'Maintenance Charges'!K3, 'Parking Violation Fines'!K3, 'Waste Management Fines'!K3, 'Pet Policy Fines'!K3, 'Noise Violation Fines'!K3, 'Property Damage Fines'!K3, 'Miscellaneous Fines'!K3 ) | L3: =SUM( 'Maintenance Charges'!L3, 'Parking Violation Fines'!L3, 'Waste Management Fines'!L3, 'Pet Policy Fines'!L3, 'Noise Violation Fines'!L3, 'Property Damage Fines'!L3, 'Miscellaneous Fines'!L3 ) | M3: =SUM( 'Maintenance Charges'!M3, 'Parking Violation Fines'!M3, 'Waste Management Fines'!M3, 'Pet Policy Fines'!M3, 'Noise Violation Fines'!M3, 'Property Damage Fines'!M3, 'Miscellaneous Fines'!M3 ) | N3: =SUM( 'Maintenance Charges'!N3, 'Parking Violation Fines'!N3, 'Waste Management Fines'!N3, 'Pet Policy Fines'!N3, 'Noise Violation Fines'!N3, 'Property Damage Fines'!N3, 'Miscellaneous Fines'!N3 ) | O3: =SUM( 'Maintenance Charges'!O3, 'Parking Violation Fines'!O3, 'Waste Management Fines'!O3, 'Pet Policy Fines'!O3, 'Noise Violation Fines'!O3, 'Property Damage Fines'!O3, 'Miscellaneous Fines'!O3 ) | P3: =SUM( 'Maintenance Charges'!P3, 'Parking Violation Fines'!P3, 'Waste Management Fines'!P3, 'Pet Policy Fines'!P3, 'Noise Violation Fines'!P3, 'Property Damage Fines'!P3, 'Miscellaneous Fines'!P3 ) | ... T3: =SUM( 'Maintenance Charges'!T3, 'Parking Violation Fines'!T3, 'Waste Management Fines'!T3, 'Pet Policy Fines'!T3, 'Noise Violation Fines'!T3, 'Property Damage Fines'!T3, 'Miscellaneous Fines'!T3 )
A4: 103 | B4: Mansi Khanna | C4: Mansi Khanna | D4: Owner | E4: mansi_khanna@demooutlook.com | F4: 2235116155 | G4: mansi_khanna@demooutlook.com | H4: 2235116155 | I4: =SUM( 'Maintenance Charges'!I4, 'Parking Violation Fines'!I4, 'Waste Management Fines'!I4, 'Pet Policy Fines'!I4, 'Noise Violation Fines'!I4, 'Property Damage Fines'!I4, 'Miscellaneous Fines'!I4 ) | J4: =SUM( 'Maintenance Charges'!J4, 'Parking Violation Fines'!J4, 'Waste Management Fines'!J4, 'Pet Policy Fines'!J4, 'Noise Violation Fines'!J4, 'Property Damage Fines'!J4, 'Miscellaneous Fines'!J4 ) | K4: =SUM( 'Maintenance Charges'!K4, 'Parking Violation Fines'!K4, 'Waste Management Fines'!K4, 'Pet Policy Fines'!K4, 'Noise Violation Fines'!K4, 'Property Damage Fines'!K4, 'Miscellaneous Fines'!K4 ) | L4: =SUM( 'Maintenance Charges'!L4, 'Parking Violation Fines'!L4, 'Waste Management Fines'!L4, 'Pet Policy Fines'!L4, 'Noise Violation Fines'!L4, 'Property Damage Fines'!L4, 'Miscellaneous Fines'!L4 ) | M4: =SUM( 'Maintenance Charges'!M4, 'Parking Violation Fines'!M4, 'Waste Management Fines'!M4, 'Pet Policy Fines'!M4, 'Noise Violation Fines'!M4, 'Property Damage Fines'!M4, 'Miscellaneous Fines'!M4 ) | N4: =SUM( 'Maintenance Charges'!N4, 'Parking Violation Fines'!N4, 'Waste Management Fines'!N4, 'Pet Policy Fines'!N4, 'Noise Violation Fines'!N4, 'Property Damage Fines'!N4, 'Miscellaneous Fines'!N4 ) | O4: =SUM( 'Maintenance Charges'!O4, 'Parking Violation Fines'!O4, 'Waste Management Fines'!O4, 'Pet Policy Fines'!O4, 'Noise Violation Fines'!O4, 'Property Damage Fines'!O4, 'Miscellaneous Fines'!O4 ) | P4: =SUM( 'Maintenance Charges'!P4, 'Parking Violation Fines'!P4, 'Waste Management Fines'!P4, 'Pet Policy Fines'!P4, 'Noise Violation Fines'!P4, 'Property Damage Fines'!P4, 'Miscellaneous Fines'!P4 ) | ... T4: =SUM( 'Maintenance Charges'!T4, 'Parking Violation Fines'!T4, 'Waste Management Fines'!T4, 'Pet Policy Fines'!T4, 'Noise Violation Fines'!T4, 'Property Damage Fines'!T4, 'Miscellaneous Fines'!T4 )
A5: 104 | B5: Manish Mukherjee | C5: Shreya Sisodia | D5: Rental | E5: manish_mukherjee@demoyahoo.com | F5: 1618495931 | G5: shreya_sisodia@demogmail.com | H5: 1413164752 | I5: =SUM( 'Maintenance Charges'!I5, 'Parking Violation Fines'!I5, 'Waste Management Fines'!I5, 'Pet Policy Fines'!I5, 'Noise Violation Fines'!I5, 'Property Damage Fines'!I5, 'Miscellaneous Fines'!I5 ) | J5: =SUM( 'Maintenance Charges'!J5, 'Parking Violation Fines'!J5, 'Waste Management Fines'!J5, 'Pet Policy Fines'!J5, 'Noise Violation Fines'!J5, 'Property Damage Fines'!J5, 'Miscellaneous Fines'!J5 ) | K5: =SUM( 'Maintenance Charges'!K5, 'Parking Violation Fines'!K5, 'Waste Management Fines'!K5, 'Pet Policy Fines'!K5, 'Noise Violation Fines'!K5, 'Property Damage Fines'!K5, 'Miscellaneous Fines'!K5 ) | L5: =SUM( 'Maintenance Charges'!L5, 'Parking Violation Fines'!L5, 'Waste Management Fines'!L5, 'Pet Policy Fines'!L5, 'Noise Violation Fines'!L5, 'Property Damage Fines'!L5, 'Miscellaneous Fines'!L5 ) | M5: =SUM( 'Maintenance Charges'!M5, 'Parking Violation Fines'!M5, 'Waste Management Fines'!M5, 'Pet Policy Fines'!M5, 'Noise Violation Fines'!M5, 'Property Damage Fines'!M5, 'Miscellaneous Fines'!M5 ) | N5: =SUM( 'Maintenance Charges'!N5, 'Parking Violation Fines'!N5, 'Waste Management Fines'!N5, 'Pet Policy Fines'!N5, 'Noise Violation Fines'!N5, 'Property Damage Fines'!N5, 'Miscellaneous Fines'!N5 ) | O5: =SUM( 'Maintenance Charges'!O5, 'Parking Violation Fines'!O5, 'Waste Management Fines'!O5, 'Pet Policy Fines'!O5, 'Noise Violation Fines'!O5, 'Property Damage Fines'!O5, 'Miscellaneous Fines'!O5 ) | P5: =SUM( 'Maintenance Charges'!P5, 'Parking Violation Fines'!P5, 'Waste Management Fines'!P5, 'Pet Policy Fines'!P5, 'Noise Violation Fines'!P5, 'Property Damage Fines'!P5, 'Miscellaneous Fines'!P5 ) | ... T5: =SUM( 'Maintenance Charges'!T5, 'Parking Violation Fines'!T5, 'Waste Management Fines'!T5, 'Pet Policy Fines'!T5, 'Noise Violation Fines'!T5, 'Property Damage Fines'!T5, 'Miscellaneous Fines'!T5 )
A6: 105 | B6: Ayaan Naidu | C6: Ayaan Naidu | D6: Owner | E6: ayaan_naidu@demooutlook.com | F6: 1928327648 | G6: ayaan_naidu@demooutlook.com | H6: 1928327648 | I6: =SUM( 'Maintenance Charges'!I6, 'Parking Violation Fines'!I6, 'Waste Management Fines'!I6, 'Pet Policy Fines'!I6, 'Noise Violation Fines'!I6, 'Property Damage Fines'!I6, 'Miscellaneous Fines'!I6 ) | J6: =SUM( 'Maintenance Charges'!J6, 'Parking Violation Fines'!J6, 'Waste Management Fines'!J6, 'Pet Policy Fines'!J6, 'Noise Violation Fines'!J6, 'Property Damage Fines'!J6, 'Miscellaneous Fines'!J6 ) | K6: =SUM( 'Maintenance Charges'!K6, 'Parking Violation Fines'!K6, 'Waste Management Fines'!K6, 'Pet Policy Fines'!K6, 'Noise Violation Fines'!K6, 'Property Damage Fines'!K6, 'Miscellaneous Fines'!K6 ) | L6: =SUM( 'Maintenance Charges'!L6, 'Parking Violation Fines'!L6, 'Waste Management Fines'!L6, 'Pet Policy Fines'!L6, 'Noise Violation Fines'!L6, 'Property Damage Fines'!L6, 'Miscellaneous Fines'!L6 ) | M6: =SUM( 'Maintenance Charges'!M6, 'Parking Violation Fines'!M6, 'Waste Management Fines'!M6, 'Pet Policy Fines'!M6, 'Noise Violation Fines'!M6, 'Property Damage Fines'!M6, 'Miscellaneous Fines'!M6 ) | N6: =SUM( 'Maintenance Charges'!N6, 'Parking Violation Fines'!N6, 'Waste Management Fines'!N6, 'Pet Policy Fines'!N6, 'Noise Violation Fines'!N6, 'Property Damage Fines'!N6, 'Miscellaneous Fines'!N6 ) | O6: =SUM( 'Maintenance Charges'!O6, 'Parking Violation Fines'!O6, 'Waste Management Fines'!O6, 'Pet Policy Fines'!O6, 'Noise Violation Fines'!O6, 'Property Damage Fines'!O6, 'Miscellaneous Fines'!O6 ) | P6: =SUM( 'Maintenance Charges'!P6, 'Parking Violation Fines'!P6, 'Waste Management Fines'!P6, 'Pet Policy Fines'!P6, 'Noise Violation Fines'!P6, 'Property Damage Fines'!P6, 'Miscellaneous Fines'!P6 ) | ... T6: =SUM( 'Maintenance Charges'!T6, 'Parking Violation Fines'!T6, 'Waste Management Fines'!T6, 'Pet Policy Fines'!T6, 'Noise Violation Fines'!T6, 'Property Damage Fines'!T6, 'Miscellaneous Fines'!T6 )
A7: 106 | B7: Ankit Pillai | C7: Radhika Jadhav | D7: Rental | E7: ankit_pillai@demogmail.com | F7: 1564139537 | G7: radhika_jadhav@demooutlook.com | H7: 2242388496 | I7: =SUM( 'Maintenance Charges'!I7, 'Parking Violation Fines'!I7, 'Waste Management Fines'!I7, 'Pet Policy Fines'!I7, 'Noise Violation Fines'!I7, 'Property Damage Fines'!I7, 'Miscellaneous Fines'!I7 ) | J7: =SUM( 'Maintenance Charges'!J7, 'Parking Violation Fines'!J7, 'Waste Management Fines'!J7, 'Pet Policy Fines'!J7, 'Noise Violation Fines'!J7, 'Property Damage Fines'!J7, 'Miscellaneous Fines'!J7 ) | K7: =SUM( 'Maintenance Charges'!K7, 'Parking Violation Fines'!K7, 'Waste Management Fines'!K7, 'Pet Policy Fines'!K7, 'Noise Violation Fines'!K7, 'Property Damage Fines'!K7, 'Miscellaneous Fines'!K7 ) | L7: =SUM( 'Maintenance Charges'!L7, 'Parking Violation Fines'!L7, 'Waste Management Fines'!L7, 'Pet Policy Fines'!L7, 'Noise Violation Fines'!L7, 'Property Damage Fines'!L7, 'Miscellaneous Fines'!L7 ) | M7: =SUM( 'Maintenance Charges'!M7, 'Parking Violation Fines'!M7, 'Waste Management Fines'!M7, 'Pet Policy Fines'!M7, 'Noise Violation Fines'!M7, 'Property Damage Fines'!M7, 'Miscellaneous Fines'!M7 ) | N7: =SUM( 'Maintenance Charges'!N7, 'Parking Violation Fines'!N7, 'Waste Management Fines'!N7, 'Pet Policy Fines'!N7, 'Noise Violation Fines'!N7, 'Property Damage Fines'!N7, 'Miscellaneous Fines'!N7 ) | O7: =SUM( 'Maintenance Charges'!O7, 'Parking Violation Fines'!O7, 'Waste Management Fines'!O7, 'Pet Policy Fines'!O7, 'Noise Violation Fines'!O7, 'Property Damage Fines'!O7, 'Miscellaneous Fines'!O7 ) | P7: =SUM( 'Maintenance Charges'!P7, 'Parking Violation Fines'!P7, 'Waste Management Fines'!P7, 'Pet Policy Fines'!P7, 'Noise Violation Fines'!P7, 'Property Damage Fines'!P7, 'Miscellaneous Fines'!P7 ) | ... T7: =SUM( 'Maintenance Charges'!T7, 'Parking Violation Fines'!T7, 'Waste Management Fines'!T7, 'Pet Policy Fines'!T7, 'Noise Violation Fines'!T7, 'Property Damage Fines'!T7, 'Miscellaneous Fines'!T7 )
A8: 201 | B8: Abhishek Srivastava | C8: Abhishek Srivastava | D8: Owner | E8: abhishek_srivastava@demogmail.com | F8: 2101226916 | G8: abhishek_srivastava@demogmail.com | H8: 2101226916 | I8: =SUM( 'Maintenance Charges'!I8, 'Parking Violation Fines'!I8, 'Waste Management Fines'!I8, 'Pet Policy Fines'!I8, 'Noise Violation Fines'!I8, 'Property Damage Fines'!I8, 'Miscellaneous Fines'!I8 ) | J8: =SUM( 'Maintenance Charges'!J8, 'Parking Violation Fines'!J8, 'Waste Management Fines'!J8, 'Pet Policy Fines'!J8, 'Noise Violation Fines'!J8, 'Property Damage Fines'!J8, 'Miscellaneous Fines'!J8 ) | K8: =SUM( 'Maintenance Charges'!K8, 'Parking Violation Fines'!K8, 'Waste Management Fines'!K8, 'Pet Policy Fines'!K8, 'Noise Violation Fines'!K8, 'Property Damage Fines'!K8, 'Miscellaneous Fines'!K8 ) | L8: =SUM( 'Maintenance Charges'!L8, 'Parking Violation Fines'!L8, 'Waste Management Fines'!L8, 'Pet Policy Fines'!L8, 'Noise Violation Fines'!L8, 'Property Damage Fines'!L8, 'Miscellaneous Fines'!L8 ) | M8: =SUM( 'Maintenance Charges'!M8, 'Parking Violation Fines'!M8, 'Waste Management Fines'!M8, 'Pet Policy Fines'!M8, 'Noise Violation Fines'!M8, 'Property Damage Fines'!M8, 'Miscellaneous Fines'!M8 ) | N8: =SUM( 'Maintenance Charges'!N8, 'Parking Violation Fines'!N8, 'Waste Management Fines'!N8, 'Pet Policy Fines'!N8, 'Noise Violation Fines'!N8, 'Property Damage Fines'!N8, 'Miscellaneous Fines'!N8 ) | O8: =SUM( 'Maintenance Charges'!O8, 'Parking Violation Fines'!O8, 'Waste Management Fines'!O8, 'Pet Policy Fines'!O8, 'Noise Violation Fines'!O8, 'Property Damage Fines'!O8, 'Miscellaneous Fines'!O8 ) | P8: =SUM( 'Maintenance Charges'!P8, 'Parking Violation Fines'!P8, 'Waste Management Fines'!P8, 'Pet Policy Fines'!P8, 'Noise Violation Fines'!P8, 'Property Damage Fines'!P8, 'Miscellaneous Fines'!P8 ) | ... T8: =SUM( 'Maintenance Charges'!T8, 'Parking Violation Fines'!T8, 'Waste Management Fines'!T8, 'Pet Policy Fines'!T8, 'Noise Violation Fines'!T8, 'Property Damage Fines'!T8, 'Miscellaneous Fines'!T8 )
A9: 202 | B9: Reyansh Narang | C9: Parth Chatterjee | D9: Rental | E9: reyansh_narang@demoyahoo.com | F9: 1184514627 | G9: parth_chatterjee@demogmail.com | H9: 2828148932 | I9: =SUM( 'Maintenance Charges'!I9, 'Parking Violation Fines'!I9, 'Waste Management Fines'!I9, 'Pet Policy Fines'!I9, 'Noise Violation Fines'!I9, 'Property Damage Fines'!I9, 'Miscellaneous Fines'!I9 ) | J9: =SUM( 'Maintenance Charges'!J9, 'Parking Violation Fines'!J9, 'Waste Management Fines'!J9, 'Pet Policy Fines'!J9, 'Noise Violation Fines'!J9, 'Property Damage Fines'!J9, 'Miscellaneous Fines'!J9 ) | K9: =SUM( 'Maintenance Charges'!K9, 'Parking Violation Fines'!K9, 'Waste Management Fines'!K9, 'Pet Policy Fines'!K9, 'Noise Violation Fines'!K9, 'Property Damage Fines'!K9, 'Miscellaneous Fines'!K9 ) | L9: =SUM( 'Maintenance Charges'!L9, 'Parking Violation Fines'!L9, 'Waste Management Fines'!L9, 'Pet Policy Fines'!L9, 'Noise Violation Fines'!L9, 'Property Damage Fines'!L9, 'Miscellaneous Fines'!L9 ) | M9: =SUM( 'Maintenance Charges'!M9, 'Parking Violation Fines'!M9, 'Waste Management Fines'!M9, 'Pet Policy Fines'!M9, 'Noise Violation Fines'!M9, 'Property Damage Fines'!M9, 'Miscellaneous Fines'!M9 ) | N9: =SUM( 'Maintenance Charges'!N9, 'Parking Violation Fines'!N9, 'Waste Management Fines'!N9, 'Pet Policy Fines'!N9, 'Noise Violation Fines'!N9, 'Property Damage Fines'!N9, 'Miscellaneous Fines'!N9 ) | O9: =SUM( 'Maintenance Charges'!O9, 'Parking Violation Fines'!O9, 'Waste Management Fines'!O9, 'Pet Policy Fines'!O9, 'Noise Violation Fines'!O9, 'Property Damage Fines'!O9, 'Miscellaneous Fines'!O9 ) | P9: =SUM( 'Maintenance Charges'!P9, 'Parking Violation Fines'!P9, 'Waste Management Fines'!P9, 'Pet Policy Fines'!P9, 'Noise Violation Fines'!P9, 'Property Damage Fines'!P9, 'Miscellaneous Fines'!P9 ) | ... T9: =SUM( 'Maintenance Charges'!T9, 'Parking Violation Fines'!T9, 'Waste Management Fines'!T9, 'Pet Policy Fines'!T9, 'Noise Violation Fines'!T9, 'Property Damage Fines'!T9, 'Miscellaneous Fines'!T9 )
A10: 203 | B10: Ayaan Khanna | C10: Ayaan Khanna | D10: Owner | E10: ayaan_khanna@demoyahoo.com | F10: 1957015430 | G10: ayaan_khanna@demoyahoo.com | H10: 1957015430 | I10: =SUM( 'Maintenance Charges'!I10, 'Parking Violation Fines'!I10, 'Waste Management Fines'!I10, 'Pet Policy Fines'!I10, 'Noise Violation Fines'!I10, 'Property Damage Fines'!I10, 'Miscellaneous Fines'!I10 ) | J10: =SUM( 'Maintenance Charges'!J10, 'Parking Violation Fines'!J10, 'Waste Management Fines'!J10, 'Pet Policy Fines'!J10, 'Noise Violation Fines'!J10, 'Property Damage Fines'!J10, 'Miscellaneous Fines'!J10 ) | K10: =SUM( 'Maintenance Charges'!K10, 'Parking Violation Fines'!K10, 'Waste Management Fines'!K10, 'Pet Policy Fines'!K10, 'Noise Violation Fines'!K10, 'Property Damage Fines'!K10, 'Miscellaneous Fines'!K10 ) | L10: =SUM( 'Maintenance Charges'!L10, 'Parking Violation Fines'!L10, 'Waste Management Fines'!L10, 'Pet Policy Fines'!L10, 'Noise Violation Fines'!L10, 'Property Damage Fines'!L10, 'Miscellaneous Fines'!L10 ) | M10: =SUM( 'Maintenance Charges'!M10, 'Parking Violation Fines'!M10, 'Waste Management Fines'!M10, 'Pet Policy Fines'!M10, 'Noise Violation Fines'!M10, 'Property Damage Fines'!M10, 'Miscellaneous Fines'!M10 ) | N10: =SUM( 'Maintenance Charges'!N10, 'Parking Violation Fines'!N10, 'Waste Management Fines'!N10, 'Pet Policy Fines'!N10, 'Noise Violation Fines'!N10, 'Property Damage Fines'!N10, 'Miscellaneous Fines'!N10 ) | O10: =SUM( 'Maintenance Charges'!O10, 'Parking Violation Fines'!O10, 'Waste Management Fines'!O10, 'Pet Policy Fines'!O10, 'Noise Violation Fines'!O10, 'Property Damage Fines'!O10, 'Miscellaneous Fines'!O10 ) | P10: =SUM( 'Maintenance Charges'!P10, 'Parking Violation Fines'!P10, 'Waste Management Fines'!P10, 'Pet Policy Fines'!P10, 'Noise Violation Fines'!P10, 'Property Damage Fines'!P10, 'Miscellaneous Fines'!P10 ) | ... T10: =SUM( 'Maintenance Charges'!T10, 'Parking Violation Fines'!T10, 'Waste Management Fines'!T10, 'Pet Policy Fines'!T10, 'Noise Violation Fines'!T10, 'Property Damage Fines'!T10, 'Miscellaneous Fines'!T10 )
A11: 204 | B11: Nikhil Purohit | C11: Rohan Fernandes | D11: Rental | E11: nikhil_purohit@demogmail.com | F11: 1278248963 | G11: rohan_fernandes@demoyahoo.com | H11: 1465787133 | I11: =SUM( 'Maintenance Charges'!I11, 'Parking Violation Fines'!I11, 'Waste Management Fines'!I11, 'Pet Policy Fines'!I11, 'Noise Violation Fines'!I11, 'Property Damage Fines'!I11, 'Miscellaneous Fines'!I11 ) | J11: =SUM( 'Maintenance Charges'!J11, 'Parking Violation Fines'!J11, 'Waste Management Fines'!J11, 'Pet Policy Fines'!J11, 'Noise Violation Fines'!J11, 'Property Damage Fines'!J11, 'Miscellaneous Fines'!J11 ) | K11: =SUM( 'Maintenance Charges'!K11, 'Parking Violation Fines'!K11, 'Waste Management Fines'!K11, 'Pet Policy Fines'!K11, 'Noise Violation Fines'!K11, 'Property Damage Fines'!K11, 'Miscellaneous Fines'!K11 ) | L11: =SUM( 'Maintenance Charges'!L11, 'Parking Violation Fines'!L11, 'Waste Management Fines'!L11, 'Pet Policy Fines'!L11, 'Noise Violation Fines'!L11, 'Property Damage Fines'!L11, 'Miscellaneous Fines'!L11 ) | M11: =SUM( 'Maintenance Charges'!M11, 'Parking Violation Fines'!M11, 'Waste Management Fines'!M11, 'Pet Policy Fines'!M11, 'Noise Violation Fines'!M11, 'Property Damage Fines'!M11, 'Miscellaneous Fines'!M11 ) | N11: =SUM( 'Maintenance Charges'!N11, 'Parking Violation Fines'!N11, 'Waste Management Fines'!N11, 'Pet Policy Fines'!N11, 'Noise Violation Fines'!N11, 'Property Damage Fines'!N11, 'Miscellaneous Fines'!N11 ) | O11: =SUM( 'Maintenance Charges'!O11, 'Parking Violation Fines'!O11, 'Waste Management Fines'!O11, 'Pet Policy Fines'!O11, 'Noise Violation Fines'!O11, 'Property Damage Fines'!O11, 'Miscellaneous Fines'!O11 ) | P11: =SUM( 'Maintenance Charges'!P11, 'Parking Violation Fines'!P11, 'Waste Management Fines'!P11, 'Pet Policy Fines'!P11, 'Noise Violation Fines'!P11, 'Property Damage Fines'!P11, 'Miscellaneous Fines'!P11 ) | ... T11: =SUM( 'Maintenance Charges'!T11, 'Parking Violation Fines'!T11, 'Waste Management Fines'!T11, 'Pet Policy Fines'!T11, 'Noise Violation Fines'!T11, 'Property Damage Fines'!T11, 'Miscellaneous Fines'!T11 )
A12: 205 | B12: Krishna Reddy | C12: Krishna Reddy | D12: Owner | E12: krishna_reddy@demoyahoo.com | F12: 1930103105 | G12: krishna_reddy@demoyahoo.com | H12: 1930103105 | I12: =SUM( 'Maintenance Charges'!I12, 'Parking Violation Fines'!I12, 'Waste Management Fines'!I12, 'Pet Policy Fines'!I12, 'Noise Violation Fines'!I12, 'Property Damage Fines'!I12, 'Miscellaneous Fines'!I12 ) | J12: =SUM( 'Maintenance Charges'!J12, 'Parking Violation Fines'!J12, 'Waste Management Fines'!J12, 'Pet Policy Fines'!J12, 'Noise Violation Fines'!J12, 'Property Damage Fines'!J12, 'Miscellaneous Fines'!J12 ) | K12: =SUM( 'Maintenance Charges'!K12, 'Parking Violation Fines'!K12, 'Waste Management Fines'!K12, 'Pet Policy Fines'!K12, 'Noise Violation Fines'!K12, 'Property Damage Fines'!K12, 'Miscellaneous Fines'!K12 ) | L12: =SUM( 'Maintenance Charges'!L12, 'Parking Violation Fines'!L12, 'Waste Management Fines'!L12, 'Pet Policy Fines'!L12, 'Noise Violation Fines'!L12, 'Property Damage Fines'!L12, 'Miscellaneous Fines'!L12 ) | M12: =SUM( 'Maintenance Charges'!M12, 'Parking Violation Fines'!M12, 'Waste Management Fines'!M12, 'Pet Policy Fines'!M12, 'Noise Violation Fines'!M12, 'Property Damage Fines'!M12, 'Miscellaneous Fines'!M12 ) | N12: =SUM( 'Maintenance Charges'!N12, 'Parking Violation Fines'!N12, 'Waste Management Fines'!N12, 'Pet Policy Fines'!N12, 'Noise Violation Fines'!N12, 'Property Damage Fines'!N12, 'Miscellaneous Fines'!N12 ) | O12: =SUM( 'Maintenance Charges'!O12, 'Parking Violation Fines'!O12, 'Waste Management Fines'!O12, 'Pet Policy Fines'!O12, 'Noise Violation Fines'!O12, 'Property Damage Fines'!O12, 'Miscellaneous Fines'!O12 ) | P12: =SUM( 'Maintenance Charges'!P12, 'Parking Violation Fines'!P12, 'Waste Management Fines'!P12, 'Pet Policy Fines'!P12, 'Noise Violation Fines'!P12, 'Property Damage Fines'!P12, 'Miscellaneous Fines'!P12 ) | ... T12: =SUM( 'Maintenance Charges'!T12, 'Parking Violation Fines'!T12, 'Waste Management Fines'!T12, 'Pet Policy Fines'!T12, 'Noise Violation Fines'!T12, 'Property Damage Fines'!T12, 'Miscellaneous Fines'!T12 )
A13: 206 | B13: Krishna Bhat | C13: Krishna Bhat | D13: Owner | E13: krishna_bhat@demoyahoo.com | F13: 2382997376 | G13: krishna_bhat@demoyahoo.com | H13: 2382997376 | I13: =SUM( 'Maintenance Charges'!I13, 'Parking Violation Fines'!I13, 'Waste Management Fines'!I13, 'Pet Policy Fines'!I13, 'Noise Violation Fines'!I13, 'Property Damage Fines'!I13, 'Miscellaneous Fines'!I13 ) | J13: =SUM( 'Maintenance Charges'!J13, 'Parking Violation Fines'!J13, 'Waste Management Fines'!J13, 'Pet Policy Fines'!J13, 'Noise Violation Fines'!J13, 'Property Damage Fines'!J13, 'Miscellaneous Fines'!J13 ) | K13: =SUM( 'Maintenance Charges'!K13, 'Parking Violation Fines'!K13, 'Waste Management Fines'!K13, 'Pet Policy Fines'!K13, 'Noise Violation Fines'!K13, 'Property Damage Fines'!K13, 'Miscellaneous Fines'!K13 ) | L13: =SUM( 'Maintenance Charges'!L13, 'Parking Violation Fines'!L13, 'Waste Management Fines'!L13, 'Pet Policy Fines'!L13, 'Noise Violation Fines'!L13, 'Property Damage Fines'!L13, 'Miscellaneous Fines'!L13 ) | M13: =SUM( 'Maintenance Charges'!M13, 'Parking Violation Fines'!M13, 'Waste Management Fines'!M13, 'Pet Policy Fines'!M13, 'Noise Violation Fines'!M13, 'Property Damage Fines'!M13, 'Miscellaneous Fines'!M13 ) | N13: =SUM( 'Maintenance Charges'!N13, 'Parking Violation Fines'!N13, 'Waste Management Fines'!N13, 'Pet Policy Fines'!N13, 'Noise Violation Fines'!N13, 'Property Damage Fines'!N13, 'Miscellaneous Fines'!N13 ) | O13: =SUM( 'Maintenance Charges'!O13, 'Parking Violation Fines'!O13, 'Waste Management Fines'!O13, 'Pet Policy Fines'!O13, 'Noise Violation Fines'!O13, 'Property Damage Fines'!O13, 'Miscellaneous Fines'!O13 ) | P13: =SUM( 'Maintenance Charges'!P13, 'Parking Violation Fines'!P13, 'Waste Management Fines'!P13, 'Pet Policy Fines'!P13, 'Noise Violation Fines'!P13, 'Property Damage Fines'!P13, 'Miscellaneous Fines'!P13 ) | ... T13: =SUM( 'Maintenance Charges'!T13, 'Parking Violation Fines'!T13, 'Waste Management Fines'!T13, 'Pet Policy Fines'!T13, 'Noise Violation Fines'!T13, 'Property Damage Fines'!T13, 'Miscellaneous Fines'!T13 )
... A109: 1806 | B109: Ananya Chaudhary | C109: Nandini Nair | D109: Rental | E109: ananya_chaudhary@demoyahoo.com | F109: 2188442258 | G109: nandini_nair@demogmail.com | H109: 1323705895 | I109: =SUM( 'Maintenance Charges'!I109, 'Parking Violation Fines'!I109, 'Waste Management Fines'!I109, 'Pet Policy Fines'!I109, 'Noise Violation Fines'!I109, 'Property Damage Fines'!I109, 'Miscellaneous Fines'!I109 ) | J109: =SUM( 'Maintenance Charges'!J109, 'Parking Violation Fines'!J109, 'Waste Management Fines'!J109, 'Pet Policy Fines'!J109, 'Noise Violation Fines'!J109, 'Property Damage Fines'!J109, 'Miscellaneous Fines'!J109 ) | K109: =SUM( 'Maintenance Charges'!K109, 'Parking Violation Fines'!K109, 'Waste Management Fines'!K109, 'Pet Policy Fines'!K109, 'Noise Violation Fines'!K109, 'Property Damage Fines'!K109, 'Miscellaneous Fines'!K109 ) | L109: =SUM( 'Maintenance Charges'!L109, 'Parking Violation Fines'!L109, 'Waste Management Fines'!L109, 'Pet Policy Fines'!L109, 'Noise Violation Fines'!L109, 'Property Damage Fines'!L109, 'Miscellaneous Fines'!L109 ) | M109: =SUM( 'Maintenance Charges'!M109, 'Parking Violation Fines'!M109, 'Waste Management Fines'!M109, 'Pet Policy Fines'!M109, 'Noise Violation Fines'!M109, 'Property Damage Fines'!M109, 'Miscellaneous Fines'!M109 ) | N109: =SUM( 'Maintenance Charges'!N109, 'Parking Violation Fines'!N109, 'Waste Management Fines'!N109, 'Pet Policy Fines'!N109, 'Noise Violation Fines'!N109, 'Property Damage Fines'!N109, 'Miscellaneous Fines'!N109 ) | O109: =SUM( 'Maintenance Charges'!O109, 'Parking Violation Fines'!O109, 'Waste Management Fines'!O109, 'Pet Policy Fines'!O109, 'Noise Violation Fines'!O109, 'Property Damage Fines'!O109, 'Miscellaneous Fines'!O109 ) | P109: =SUM( 'Maintenance Charges'!P109, 'Parking Violation Fines'!P109, 'Waste Management Fines'!P109, 'Pet Policy Fines'!P109, 'Noise Violation Fines'!P109, 'Property Damage Fines'!P109, 'Miscellaneous Fines'!P109 ) | ... T109: =SUM( 'Maintenance Charges'!T109, 'Parking Violation Fines'!T109, 'Waste Management Fines'!T109, 'Pet Policy Fines'!T109, 'Noise Violation Fines'!T109, 'Property Damage Fines'!T109, 'Miscellaneous Fines'!T109 )

Sheet Payments
A1: Flat No. | B1: Owner Name | C1: Resident Name | D1: Occupancy Type | E1: Owner Email | F1: Owner Mobile | G1: Resident Email | H1: Resident Mobile | I1: Jan-26 | J1: Feb-26 | K1: Mar-26 | L1: Apr-26 | M1: May-26 | N1: Jun-26 | O1: Jul-26 | P1: Aug-26 | Q1: Sep-26 | R1: Oct-26 | S1: Nov-26 | T1: Dec-26
A2: 101 | B2: Meera Bhatt | C2: Meera Bhatt | D2: Owner | E2: meera_bhatt@demooutlook.com | F2: 1321819600 | G2: meera_bhatt@demooutlook.com | H2: 1321819600 | I2: Paid | J2: Paid | K2: Paid | L2: Paid | M2: Paid | N2: Paid | O2: Paid | P2: 0 | Q2: 0 | R2: 0 | S2: 0 | T2: 0
A3: 102 | B3: Rohan Gill | C3: Rohan Gill | D3: Owner | E3: rohan_gill@demoyahoo.com | F3: 1838637940 | G3: rohan_gill@demoyahoo.com | H3: 1838637940 | I3: Paid | J3: Paid | K3: Paid | L3: Paid | M3: Paid | N3: Paid | O3: Paid | P3: 0 | Q3: 0 | R3: 0 | S3: 0 | T3: 0
A4: 103 | B4: Mansi Khanna | C4: Mansi Khanna | D4: Owner | E4: mansi_khanna@demooutlook.com | F4: 2235116155 | G4: mansi_khanna@demooutlook.com | H4: 2235116155 | I4: Paid | J4: Paid | K4: Paid | L4: Paid | M4: Paid | N4: Paid | O4: Paid | P4: 0 | Q4: 0 | R4: 0 | S4: 0 | T4: 0
A5: 104 | B5: Manish Mukherjee | C5: Shreya Sisodia | D5: Rental | E5: manish_mukherjee@demoyahoo.com | F5: 1618495931 | G5: shreya_sisodia@demogmail.com | H5: 1413164752 | I5: 3500 | J5: 3500 | K5: 2000 | L5: Paid | M5: Paid | N5: Paid | O5: Paid | P5: 0 | Q5: 0 | R5: 0 | S5: 0 | T5: 0
A6: 105 | B6: Ayaan Naidu | C6: Ayaan Naidu | D6: Owner | E6: ayaan_naidu@demooutlook.com | F6: 1928327648 | G6: ayaan_naidu@demooutlook.com | H6: 1928327648 | I6: Paid | J6: Paid | K6: Paid | L6: Paid | M6: Paid | N6: Paid | O6: Paid | P6: 0 | Q6: 0 | R6: 0 | S6: 0 | T6: 0
A7: 106 | B7: Ankit Pillai | C7: Radhika Jadhav | D7: Rental | E7: ankit_pillai@demogmail.com | F7: 1564139537 | G7: radhika_jadhav@demooutlook.com | H7: 2242388496 | I7: Paid | J7: Paid | K7: Paid | L7: Paid | M7: Paid | N7: Paid | O7: Paid | P7: 0 | Q7: 0 | R7: 0 | S7: 0 | T7: 0
A8: 201 | B8: Abhishek Srivastava | C8: Abhishek Srivastava | D8: Owner | E8: abhishek_srivastava@demogmail.com | F8: 2101226916 | G8: abhishek_srivastava@demogmail.com | H8: 2101226916 | I8: Paid | J8: Paid | K8: Paid | L8: Paid | M8: Paid | N8: Paid | O8: Paid | P8: 0 | Q8: 0 | R8: 0 | S8: 0 | T8: 0
A9: 202 | B9: Reyansh Narang | C9: Parth Chatterjee | D9: Rental | E9: reyansh_narang@demoyahoo.com | F9: 1184514627 | G9: parth_chatterjee@demogmail.com | H9: 2828148932 | I9: Paid | J9: Paid | K9: Paid | L9: Paid | M9: Paid | N9: Paid | O9: Paid | P9: 0 | Q9: 0 | R9: 0 | S9: 0 | T9: 0
A10: 203 | B10: Ayaan Khanna | C10: Ayaan Khanna | D10: Owner | E10: ayaan_khanna@demoyahoo.com | F10: 1957015430 | G10: ayaan_khanna@demoyahoo.com | H10: 1957015430 | I10: Paid | J10: Paid | K10: Paid | L10: Paid | M10: Paid | N10: Paid | O10: Paid | P10: 0 | Q10: 0 | R10: 0 | S10: 0 | T10: 0
A11: 204 | B11: Nikhil Purohit | C11: Rohan Fernandes | D11: Rental | E11: nikhil_purohit@demogmail.com | F11: 1278248963 | G11: rohan_fernandes@demoyahoo.com | H11: 1465787133 | I11: Paid | J11: Paid | K11: Paid | L11: Paid | M11: Paid | N11: Paid | O11: Paid | P11: 0 | Q11: 0 | R11: 0 | S11: 0 | T11: 0
A12: 205 | B12: Krishna Reddy | C12: Krishna Reddy | D12: Owner | E12: krishna_reddy@demoyahoo.com | F12: 1930103105 | G12: krishna_reddy@demoyahoo.com | H12: 1930103105 | I12: Paid | J12: Paid | K12: Paid | L12: Paid | M12: Paid | N12: Paid | O12: Paid | P12: 0 | Q12: 0 | R12: 0 | S12: 0 | T12: 0
